<!-- ======================================================
	The Barrett WAM 7 DoF setup as in the IAS Lab @ TU Darmstadt

	Last edits 	: 18Dec'19
====================================================== -->

<mujoco model="wam_7dof">
    <option integrator="Euler" timestep="0.002"/>
    <compiler coordinate="local" angle="radian" meshdir="meshes/"/>
    <default>
        <joint type="hinge" limited="true" pos="0 0 0" axis="0 0 1" frictionloss=".1"/>
        <default class="viz">
            <geom type="mesh" contype="0" conaffinity="0" group="2" rgba="0.7 0.7 0.7 1" density="0"/>
        </default>
        <default class="col">
            <geom type="mesh" contype="0" conaffinity="1" group="3" rgba="0.5 0.6 0.7 1" density="0"/>
        </default>
         <default class="x_axis">
            <geom contype="0" conaffinity="0" group="1" rgba="1 0 0 1"
                  type="cylinder" size=".01 0.15" pos="0.15 0 0" euler="0 1.570796327 0"/>
        </default>
        <default class="y_axis">
            <geom contype="0" conaffinity="0" group="1" rgba="0 1 0 1"
                  type="cylinder" size=".01 0.15" pos="0 0.15 0" euler="1.570796327 0 0"/>
        </default>
        <default class="z_axis">
            <geom contype="0" conaffinity="0" group="1" rgba="0 0 1 1"
                  type="cylinder" size=".01 0.15" pos="0 0 0.15" euler="0 0 0"/>
        </default>
    </default>

    <asset>
        <mesh file="base_link_fine.stl"/>
        <mesh file="base_link_convex.stl"/>
        <mesh file="shoulder_link_fine.stl"/>
        <mesh file="shoulder_link_convex_decomposition_p1.stl"/>
        <mesh file="shoulder_link_convex_decomposition_p2.stl"/>
        <mesh file="shoulder_link_convex_decomposition_p3.stl"/>
        <mesh file="shoulder_pitch_link_fine.stl"/>
        <mesh file="shoulder_pitch_link_convex.stl"/>
        <mesh file="upper_arm_link_fine.stl"/>
        <mesh file="upper_arm_link_convex_decomposition_p1.stl"/>
        <mesh file="upper_arm_link_convex_decomposition_p2.stl"/>
        <mesh file="elbow_link_fine.stl"/>
        <mesh file="elbow_link_convex.stl"/>
        <mesh file="forearm_link_fine.stl"/>
        <mesh file="forearm_link_convex_decomposition_p1.stl"/>
        <mesh file="forearm_link_convex_decomposition_p2.stl"/>
        <mesh file="wrist_yaw_link_fine.stl"/>
        <mesh file="wrist_yaw_link_convex_decomposition_p1.stl"/>
        <mesh file="wrist_yaw_link_convex_decomposition_p2.stl"/>
        <mesh file="wrist_pitch_link_fine.stl"/>
        <mesh file="wrist_pitch_link_convex_decomposition_p1.stl"/>
        <mesh file="wrist_pitch_link_convex_decomposition_p2.stl"/>
        <mesh file="wrist_pitch_link_convex_decomposition_p3.stl"/>
        <mesh file="wrist_palm_link_fine.stl"/>
        <mesh file="wrist_palm_link_convex.stl"/>

        <texture name="texplane" type="2d" builtin="checker" rgb1=".2 .3 .4" rgb2=".1 0.15 0.2" width="512"
                 height="512" mark="cross" markrgb=".8 .8 .8"/>
        <material name="matplane" reflectance="0.3" texture="texplane" texrepeat="1 1" texuniform="true"/>

    </asset>

    <worldbody>
        <light directional="false" diffuse=".2 .2 .2" specular="0 0 0" pos="0 0 5" dir="0 0 -1" castshadow="false"/>
        <light mode="targetbodycom" target="wam/links/base" directional="false" diffuse="2 2 2" specular="0.3 0.3 0.3" pos="0 0 4.0" dir="0 0 -1"/>
        <geom name="floor" pos="0 0 0" size="2 2 .25" type="plane" material="matplane" condim="3" solref="-16000 -200"/>
        <geom class="x_axis"/>
        <geom class="y_axis"/>
        <geom class="z_axis"/>

        <body name="wam/links/base" pos="0 0 .84" euler="0 0 1.570796327">
            <geom class="x_axis"/>
            <geom class="y_axis"/>
            <geom class="z_axis"/>
            <geom class="viz" mesh="base_link_fine" euler="0 0 -1.570796327"/>
            <geom class="col" mesh="base_link_convex" euler="0 0 -1.570796327"/>

            <body name="wam/links/shoulder_yaw" pos="0 0 0.160" euler="0 0 -1.570796327">
                <inertial pos="-0.00443422 -0.00066489 -0.12189039" mass="10.76768767" fullinertia="0.50739925 0.46298222 0.11328369 0.00012485 -0.00213041 0.00068555" />
                <site name="wam/mass_sites/shoulder_yaw" pos="-0.00443422 -0.00066489 -0.12189039"/>
                <joint name="wam/joints/base_yaw" range="-2.6 2.6" />
                <geom class="viz" mesh="shoulder_link_fine" pos="0 0 0.186"/>
                <geom class="col" mesh="shoulder_link_convex_decomposition_p1" pos="0 0 0.186"/>
                <geom class="col" mesh="shoulder_link_convex_decomposition_p2" pos="0 0 0.186"/>
                <geom class="col" mesh="shoulder_link_convex_decomposition_p3" pos="0 0 0.186"/>

                <body name="wam/links/shoulder_pitch" pos="0 0 0.184" quat="0.707107 -0.707107 0 0">
                    <inertial pos="-0.00236983 -0.01542114 0.03105614" mass="3.87493756" fullinertia="0.02140958 0.01558906 0.01377875 0.00002461 -0.00027172 -0.00181920" />
                    <site name="wam/mass_sites/shoulder_pitch" pos="-0.00236983 -0.01542114 0.03105614"/>
                    <joint name="wam/joints/shoulder_pitch_joint" range="-1.985 1.985" />
                    <geom class="viz" mesh="shoulder_pitch_link_fine"/>
                    <geom class="col" mesh="shoulder_pitch_link_convex"/>

                    <body name="wam/links/upper_arm" pos="0 -0.505 0" quat="0.707107 0.707107 0 0">
                        <inertial pos="-0.03825858 0.00003309 -0.20750770" mass="1.80228141" fullinertia="0.06276039 0.06656967 0.00689512 -0.00000738 -0.00614574 -0.00001767" />
                        <site name="wam/mass_sites/upper_arm" pos="-0.03825858 0.00003309 -0.20750770"/>
                        <joint name="wam/joints/shoulder_yaw" range="-2.8 2.8" />
                        <geom class="viz" mesh="upper_arm_link_fine" pos="0 0 -0.505"/>
                        <geom class="col" mesh="upper_arm_link_convex_decomposition_p1" pos="0 0 -0.505"/>
                        <geom class="col" mesh="upper_arm_link_convex_decomposition_p2" pos="0 0 -0.505"/>

                        <body name="wam/links/forearm" pos="0.045 0 0.045" quat="0.707107 -0.707107 0 0">
                            <inertial pos="0.00498512 -0.13271662 -0.00022942" mass="2.40016804" fullinertia="0.01491672 0.00780497 0.01968956 -0.00150604 -0.00001741 -0.00002109" />
                            <site name="wam/mass_sites/forearm" pos="0.00498512 -0.13271662 -0.00022942"/>
                            <joint name="wam/joints/elbow_pitch" range="-0.9 3.14159" />
                            <geom class="viz" mesh="elbow_link_fine"/>
                            <geom class="col" mesh="elbow_link_convex"/>
                            <geom class="viz" mesh="forearm_link_fine" pos="-.045 -0.0730 0" euler="1.57 0 0"/>
                            <geom class="col" mesh="forearm_link_convex_decomposition_p1" pos="-0.045 -0.0730 0" euler="1.57 0 0"/>
                            <geom class="col" mesh="forearm_link_convex_decomposition_p2" pos="-.045 -0.0730 0" euler="1.57 0 0"/>

                            <body name="wam/links/wrist_yaw" pos="-0.045 0 0" quat="0.707107 0.707107 0 0">
                                <inertial pos="0.00008921 0.00435824 -0.00511217" mass="0.12376019" fullinertia="0.01118871 0.01120112 0.00007582 0.00000005 0.00000020 -0.00000359" />
                                <site name="wam/mass_sites/wrist_yaw" pos="0.00008921 0.00435824 -0.00511217"/>
                                <joint name="wam/joints/wrist_yaw" range="-4.55 1.25" />
                                <geom class="viz" mesh="wrist_yaw_link_fine" pos="0 0 0.3"/>
                                <geom class="col" mesh="wrist_yaw_link_convex_decomposition_p1" pos="0 0 0.3"/>
                                <geom class="col" mesh="wrist_yaw_link_convex_decomposition_p2" pos="0 0 0.3"/>

                                <body name="wam/links/wrist_pitch" pos="0 0 0.3" quat="0.707107 -0.707107 0 0">
                                    <inertial pos="-0.00012262 -0.02468336 -0.01703194" mass="0.41797364" fullinertia="0.00055516 0.00045358 0.00024367 -0.00000074 -0.00000061 -0.00004590" />
                                    <site name="wam/mass_sites/wrist_pitch" pos="-0.00012262 -0.02468336 -0.01703194"/>
                                    <joint name="wam/joints/wrist_pitch" range="-1.5707 1.5707" />
                                    <geom class="viz" mesh="wrist_pitch_link_fine" pos="0 0 0"/>
                                    <geom class="col" mesh="wrist_pitch_link_convex_decomposition_p1"/>
                                    <geom class="col" mesh="wrist_pitch_link_convex_decomposition_p2"/>
                                    <geom class="col" mesh="wrist_pitch_link_convex_decomposition_p3"/>

                                    <body name="wam/links/wrist_palm" pos="0 -0.06 0" quat="0.707107 0.707107 0 0">
                                        <inertial pos="-0.00007974 -0.00323552 -0.00016313" mass="0.06864753" fullinertia="0.00003773 0.00007408 0.00003806 0.00000000 -0.00000019 0.00000000" />
                                        <site name="wam/mass_sites/wrist_palm" pos="-0.00007974 -0.00323552 -0.00016313"/>
                                        <joint name="wam/joints/palm_yaw" range="-2.7 2.7" />
                                        <geom class="viz" mesh="wrist_palm_link_fine" pos="0 0 -0.06"/>
                                        <geom class="x_axis"/>
                                        <geom class="y_axis"/>
                                        <geom class="z_axis"/>

                                        <!-- Include your endeffector here via: -->
                                        <!--<include file="file_name.robot_description"/>-->

                                        <!-- Note that the XML Tags in this XML file should be enclosed by the following
                                        parent XML Tag
                                        <mujocoinclude>
                                        ...
                                        </mujocoinclude>-->

                                    </body>
                                </body>
                            </body>
                        </body>
                    </body>
                </body>
            </body>
        </body>
    </worldbody>
</mujoco>
